2014-04-28 17:10:17 ERROR Error handling request
Traceback (most recent call last):
File "/usr/lib/python2.6/site-packages/gunicorn/workers/async.py", line 45, in handle
self.handle_request(listener, req, client, addr)
File "/usr/lib/python2.6/site-packages/gunicorn/workers/ggevent.py", line 151, in handle_request
super(GeventWorker, self).handle_request(*args)
File "/usr/lib/python2.6/site-packages/gunicorn/workers/async.py", line 93, in handle_request
respiter = self.wsgi(environ, resp.start_response)
File "/usr/lib/python2.6/site-packages/pyramid/router.py", line 251, in __call__
response = self.invoke_subrequest(request, use_tweens=True)
File "/usr/lib/python2.6/site-packages/pyramid/router.py", line 227, in invoke_subrequest
response = handle_request(request)
File "/usr/lib/python2.6/site-packages/eucaconsole/tweens.py", line 22, in tween
response = handler(request)
File "/usr/lib/python2.6/site-packages/eucaconsole/tweens.py", line 12, in tween
response = handler(request)
File "/usr/lib/python2.6/site-packages/pyramid/tweens.py", line 21, in excview_tween
response = handler(request)
File "/usr/lib/python2.6/site-packages/pyramid/router.py", line 161, in handle_request
response = view_callable(context, request)
File "/usr/lib/python2.6/site-packages/pyramid/config/views.py", line 319, in attr_view
return view(context, request)
File "/usr/lib/python2.6/site-packages/pyramid/config/views.py", line 295, in predicate_wrapper
return view(context, request)
File "/usr/lib/python2.6/site-packages/pyramid/config/views.py", line 237, in _secured_view
return view(context, request)
File "/usr/lib/python2.6/site-packages/pyramid/config/views.py", line 345, in rendered_view
result = view(context, request)
File "/usr/lib/python2.6/site-packages/pyramid/config/views.py", line 462, in _class_requestonly_view
inst = view(request)
File "/usr/lib/python2.6/site-packages/eucaconsole/views/snapshots.py", line 194, in __init__
self.images_registered = self.get_images_registered(self.snapshot.id) if self.snapshot else None
File "/usr/lib64/python2.6/contextlib.py", line 34, in __exit__
self.gen.throw(type, value, traceback)
File "/usr/lib/python2.6/site-packages/eucaconsole/views/__init__.py", line 419, in boto_error_handler
yield
File "/usr/lib/python2.6/site-packages/eucaconsole/views/snapshots.py", line 194, in __init__
self.images_registered = self.get_images_registered(self.snapshot.id) if self.snapshot else None
File "/usr/lib/python2.6/site-packages/eucaconsole/views/snapshots.py", line 215, in get_images_registered
vol = img.block_device_mapping[self.get_root_device_name(img)]
KeyError: u'/dev/sda1'
